<?xml version="1.0" ?>
<sdf version="1.8">
    <model name='vehicle'>
        <link name='chassis'>
            <pose>-0.075714 0 0.147181 0 0 0</pose>
            <inertial>
                <mass>0.571975</mass>
                <inertia>
                    <ixx>0.063082</ixx>
                    <ixy>0</ixy>
                    <ixz>0</ixz>
                    <iyy>0.2082595</iyy>
                    <iyz>0</iyz>
                    <izz>0.240507</izz>
                </inertia>
            </inertial>
            <visual name='visual_chassis'>
                <geometry>
                    <box>
                        <size>1.00571 0.5 0.284363</size>
                    </box>
                </geometry>
                <material>
                    <ambient>0.5 0.5 1.0 1</ambient>
                    <diffuse>0.5 0.5 1.0 1</diffuse>
                    <specular>0.0 0.0 1.0 1</specular>
                </material>
            </visual>
            <collision name='collision_chassis'>
                <geometry>
                    <box>
                        <size>1.00571 0.5 0.284363</size>
                    </box>
                </geometry>
            </collision>
        </link>

        <link name='camera'>
            <pose>0 0 0.45 0 0 0</pose>
            <inertial>
              <mass>0.3</mass>
              <inertia>
                <ixx>0.005</ixx>
                <ixy>0</ixy>
                <ixz>0</ixz>
                <iyy>0.005</iyy>
                <iyz>0</iyz>
                <izz>0.005</izz>
              </inertia>
            </inertial>
            <visual name='visual_camera'>
              <geometry>
                <box>
                  <size>0.3 0.3 0.1</size>
                </box>
              </geometry>
              <material>
                <ambient>0.7 0.7 0.7 1</ambient>
                <diffuse>0.7 0.7 0.7 1</diffuse>
                <specular>0.3 0.3 0.3 1</specular>
              </material>
            </visual>
            <sensor name="camera" type="camera">
              <camera>
                <horizontal_fov>1.047</horizontal_fov>
                <image>
                  <width>320</width>
                  <height>240</height>
                </image>
                <clip>
                  <near>0.1</near>
                  <far>100</far>
                </clip>
              </camera>
              <always_on>1</always_on>
              <update_rate>30</update_rate>
              <visualize>true</visualize>
              <topic>camera</topic>
            </sensor>
            <collision name='collision_camera'>
              <geometry>
                <box>
                  <size>0.3 0.3 0.1</size>
                </box>
              </geometry>
            </collision>
        </link>
    
        <joint name='camera_joint' type='fixed'>
            <parent>chassis</parent>
            <child>camera</child>
        </joint>

        <link name='left_wheel'>
            <pose>0.277142 0.3125145 -0.0125 -1.5707 0 0</pose>
            <inertial>
                <mass>1</mass>
                <inertia>
                    <ixx>0.0729165</ixx>
                    <ixy>0</ixy>
                    <ixz>0</ixz>
                    <iyy>0.0729165</iyy>
                    <iyz>0</iyz>
                    <izz>0.0625</izz>
                </inertia>
            </inertial>
            <visual name='visual_left_wheel'>
                <geometry>
                    <sphere>
                        <radius>0.15</radius>
                    </sphere>
                </geometry>
                <material>
                    <ambient>0.2 0.2 0.2 1</ambient>
                    <diffuse>0.2 0.2 0.2 1</diffuse>
                    <specular>0.2 0.2 0.2 1</specular>
                </material>
            </visual>
            <collision name='collision_left_wheel'>
                <geometry>
                    <sphere>
                        <radius>0.15</radius>
                    </sphere>
                </geometry>
            </collision>
        </link>

        <link name='right_wheel'>
            <pose>0.277141 -0.3125145 -0.0125 -1.5707 0 0</pose>
            <inertial>
                <mass>1</mass>
                <inertia>
                    <ixx>0.0729165</ixx>
                    <ixy>0</ixy>
                    <ixz>0</ixz>
                    <iyy>0.0729165</iyy>
                    <iyz>0</iyz>
                    <izz>0.0625</izz>
                </inertia>
            </inertial>
            <visual name='visual_right_wheel'>
                <geometry>
                    <sphere>
                        <radius>0.15</radius>
                    </sphere>
                </geometry>
                <material>
                    <ambient>0.2 0.2 0.2 1</ambient>
                    <diffuse>0.2 0.2 0.2 1</diffuse>
                    <specular>0.2 0.2 0.2 1</specular>
                </material>
            </visual>
            <collision name='collision_right_wheel'>
                <geometry>
                    <sphere>
                        <radius>0.15</radius>
                    </sphere>
                </geometry>
            </collision>
        </link>

        <link name='caster'>
            <pose>-0.478569 0 -0.0625 0 -0 0</pose>
            <inertial>
                <mass>0.5</mass>
                <inertia>
                    <ixx>0.05</ixx>
                    <ixy>0</ixy>
                    <ixz>0</ixz>
                    <iyy>0.05</iyy>
                    <iyz>0</iyz>
                    <izz>0.05</izz>
                </inertia>
            </inertial>
            <visual name='visual_caster'>
                <geometry>
                    <sphere>
                        <radius>0.1</radius>
                    </sphere>
                </geometry>
                <material>
                    <ambient>0.2 0.2 0.2 1</ambient>
                    <diffuse>0.2 0.2 0.2 1</diffuse>
                    <specular>0.2 0.2 0.2 1</specular>
                </material>
            </visual>
            <collision name='collision_caster'>
                <geometry>
                    <sphere>
                        <radius>0.1</radius>
                    </sphere>
                </geometry>
            </collision>
        </link>

        <joint name='left_wheel_joint' type='revolute'>
            <parent>chassis</parent>
            <child>left_wheel</child>
            <axis>
                <xyz>0 0 1</xyz>
                <limit>
                    <lower>-1.79769e+308</lower>
                    <upper>1.79769e+308</upper>
                </limit>
            </axis>
        </joint>

        <joint name='right_wheel_joint' type='revolute'>
            <parent>chassis</parent>
            <child>right_wheel</child>
            <axis>
                <xyz>0 0 1</xyz>
                <limit>
                    <lower>-1.79769e+308</lower>
                    <upper>1.79769e+308</upper>
                </limit>
            </axis>
        </joint>

        <joint name='caster_wheel' type='ball'>
            <parent>chassis</parent>
            <child>caster</child>
        </joint>

        <plugin
            filename="ignition-gazebo-diff-drive-system"
            name="ignition::gazebo::systems::DiffDrive">
            <left_joint>left_wheel_joint</left_joint>
            <right_joint>right_wheel_joint</right_joint>
            <wheel_separation>0.625</wheel_separation>
            <wheel_radius>0.15</wheel_radius>
            <odom_publish_frequency>1</odom_publish_frequency>
            <max_linear_acceleration>1</max_linear_acceleration>
            <min_linear_acceleration>-1</min_linear_acceleration>
            <max_angular_acceleration>2</max_angular_acceleration>
            <min_angular_acceleration>-2</min_angular_acceleration>
            <max_linear_velocity>0.5</max_linear_velocity>
            <min_linear_velocity>-0.5</min_linear_velocity>
            <max_angular_velocity>1</max_angular_velocity>
            <min_angular_velocity>-1</min_angular_velocity>
        </plugin>

    </model>
</sdf>
